Workbook
Name D_TA_A_1_1: '[1]DV-Lists'!$M$9:$M$13
Name D_TA_A_2_1: '[1]DV-Lists'!$O$9:$O$13
Name D_TA_A_3_1: '[1]DV-Lists'!$Q$9:$Q$13
Name D_TA_B_1_1: '[1]DV-Lists'!$N$9:$N$13
Name D_TA_B_2_1: '[1]DV-Lists'!$P$9:$P$13
Name D_TA_B_3_1: '[1]DV-Lists'!$R$9:$R$13

Sheet initial - circa 2022
A1: Feature Category | B1: Feature | C1: QuestionID | D1: Question | E1: Answer
A2: =lookup!A2 -> Process integration | B2: =lookup!B2 -> maintenance and review frequency | C2: =lookup!C2 -> QFPI1.1 | D2: =_xlfn.XLOOKUP('initial - circa 2022'!C2,lookup!C2:C44,lookup!D2:D44,FALSE) -> How often the threat models are reviewed and maintained? | E2: No defined frequency | F2: =_xlfn.XLOOKUP(E2,lookup!E2:E5,lookup!F2:F5,FALSE) -> 0
B3: =lookup!B6 -> Threat Modeling process engagement | C3: =lookup!C6 -> QFPI2.1 | D3: =_xlfn.XLOOKUP('initial - circa 2022'!C3,lookup!C3:C45,lookup!D3:D45,FALSE) -> On what occasions TM is performed during SSDL? | E3: On ad-hoc basis | F3: =_xlfn.XLOOKUP(E3,lookup!E6:E9,lookup!F6:F9,FALSE) -> 0.33
B4: =lookup!B10 -> SSDL and TM features synergies | C4: =lookup!C10 -> QFPI3.1 | D4: =_xlfn.XLOOKUP('initial - circa 2022'!C4,lookup!C4:C46,lookup!D4:D46,FALSE) -> How current threat modeling enables and improves other aspects of security and development? | E4: Threat Models are not present or if present are mostly ignored and unused to improve other aspects of development | F4: =_xlfn.XLOOKUP(E4,lookup!E10:E13,lookup!F10:F13,FALSE) -> 0
A5: Methodology &​ granularity | B5: methodology and analysis consistency | C5: QFM1.1 | D5: =_xlfn.XLOOKUP('initial - circa 2022'!C5,lookup!C5:C47,lookup!D5:D47,FALSE) -> what methodologies are used for threat modeling? | E5: Standard methodologies for example:data flow analysis, STRIDE, attack trees, trust boundaries definition, etc. | F5: =_xlfn.XLOOKUP(E5,lookup!E14:E16,lookup!F14:F16,FALSE) -> 0.66
B6: granularity and level of abstraction | C6: QFM2.1 | D6: =_xlfn.XLOOKUP('initial - circa 2022'!C6,lookup!C6:C48,lookup!D6:D48,FALSE) -> what granularity and level of abstraction are the system analyzed at? | E6: Mostly high level of abstraction, for example Data Flow Diagrams and high level architecture and system views | F6: =_xlfn.XLOOKUP(E6,lookup!E17:E20,lookup!F17:F20,0) -> 0.5
B7: threat model scalability and composability | C7: QFM3.1 | D7: =_xlfn.XLOOKUP('initial - circa 2022'!C7,lookup!C7:C49,lookup!D7:D49,FALSE) -> How scalable are the threat models? | E7: every threat model is logically not compatible with the others threat models | F7: =_xlfn.XLOOKUP(E7,lookup!E21:E23,lookup!F21:F23,0) -> 0
A8: Staff enablement | B8: Security expertise availability (SME/training/sec champions) | C8: QFSE1.1 | D8: =_xlfn.XLOOKUP('initial - circa 2022'!C8,lookup!C8:C50,lookup!D8:D50,FALSE) -> what security expertise is available to perform threat modeling? | E8: there are SMEs for ad-hoc threat modeling | F8: =_xlfn.XLOOKUP(E8,lookup!E24:E27,lookup!F24:F27,0) -> 0.33
A9: Measurements and metrics | B9: threat modeling metrics | C9: QFMM2.1 | D9: =_xlfn.XLOOKUP('initial - circa 2022'!C9,lookup!C9:C51,lookup!D9:D51,FALSE) -> what metrics the TM process produces? | E9: no metrics | F9: =_xlfn.XLOOKUP(E9,lookup!E28:E30,lookup!F28:F30,0) -> 0
A10: Threat model lifecycle and capabilities | B10: threat model storage, format, template and tracking | C10: QFENLC1.1 | D10: =_xlfn.XLOOKUP('initial - circa 2022'!C10,lookup!C10:C52,lookup!D10:D52,FALSE) -> how are TM stored and accessible? | E10: not defined, and no consistent way to retrieve threat models | F10: =_xlfn.XLOOKUP(E10,lookup!E31:E33,lookup!F31:F33,0) -> 0
C11: QFENLC1.2 | D11: =_xlfn.XLOOKUP('initial - circa 2022'!C11,lookup!C11:C53,lookup!D11:D53,FALSE) -> what file format and template are threat models on? | E11: not defined | F11: =_xlfn.XLOOKUP(E11,lookup!E34:E36,lookup!F34:F36,0) -> 0
B12: issue tracking/gates | C12: QFIT1.1 | D12: =_xlfn.XLOOKUP('initial - circa 2022'!C12,lookup!C12:C54,lookup!D12:D54,FALSE) -> how TM outcomes and security issue management are related? | E12: on ad-hoc basis and not consistently TM findings are added to the issue tracking system | F12: =_xlfn.XLOOKUP(E12,lookup!E37:E39,lookup!F37:F39,0) -> 0.5
C13: QFIT1.2 | D13: =_xlfn.XLOOKUP('initial - circa 2022'!C13,lookup!C13:C55,lookup!D13:D55,FALSE) -> how TM analysis and its outcomes impact the release condition and gates? | E13: TM practices do not affect releases status | F13: =_xlfn.XLOOKUP(E13,lookup!E40:E42,lookup!F40:F42,0) -> 0
B19: Maturity 0 - 3
A21: Process integration | B21: =AVERAGE(F2:F4)*3 -> 0.33
A22: Methodology &​ granularity | B22: =AVERAGE(F5:F7)*3 -> 1.16
A23: Staff enablement | B23: =AVERAGE(F4:F6)*3 -> 1.16
A24: Measurements and metrics | B24: =F9*3 -> 0
A25: Threat model lifecycle and capabilities | B25: =AVERAGE(F10:F13)*3 -> 0.375
A27: Overall Maturity | B27: =AVERAGE(B21:B25) -> 0.605

Sheet phase 1 - 2023
A1: Feature Category | B1: Feature | C1: QuestionID | D1: Question | E1: Answer
A2: =lookup!A2 -> Process integration | B2: =lookup!B2 -> maintenance and review frequency | C2: =lookup!C2 -> QFPI1.1 | D2: =_xlfn.XLOOKUP('phase 1 - 2023'!C2,lookup!C2:C44,lookup!D2:D44,FALSE) -> How often the threat models are reviewed and maintained? | E2: At least annually | F2: =_xlfn.XLOOKUP(E2,lookup!E2:E5,lookup!F2:F5,FALSE) -> 0.66
B3: =lookup!B6 -> Threat Modeling process engagement | C3: =lookup!C6 -> QFPI2.1 | D3: =_xlfn.XLOOKUP('phase 1 - 2023'!C3,lookup!C3:C45,lookup!D3:D45,FALSE) -> On what occasions TM is performed during SSDL? | E3: Modelling performed as part of standard process that is loosely aligned to release processes | F3: =_xlfn.XLOOKUP(E3,lookup!E6:E9,lookup!F6:F9,FALSE) -> 0.66
B4: =lookup!B10 -> SSDL and TM features synergies | C4: =lookup!C10 -> QFPI3.1 | D4: =_xlfn.XLOOKUP('phase 1 - 2023'!C4,lookup!C4:C46,lookup!D4:D46,FALSE) -> How current threat modeling enables and improves other aspects of security and development? | E4: on ad-hoc basis threat models are used (for example as a reference documentation, or for customers request, or as compliance evidence) | F4: =_xlfn.XLOOKUP(E4,lookup!E10:E13,lookup!F10:F13,FALSE) -> 0.33
A5: Methodology &​ granularity | B5: methodology and analysis consistency | C5: QFM1.1 | D5: =_xlfn.XLOOKUP('phase 1 - 2023'!C5,lookup!C5:C47,lookup!D5:D47,FALSE) -> what methodologies are used for threat modeling? | E5: Standard methodologies for example:data flow analysis, STRIDE, attack trees, trust boundaries definition, etc. | F5: =_xlfn.XLOOKUP(E5,lookup!E14:E16,lookup!F14:F16,FALSE) -> 0.66
B6: granularity and level of abstraction | C6: QFM2.1 | D6: =_xlfn.XLOOKUP('phase 1 - 2023'!C6,lookup!C6:C48,lookup!D6:D48,FALSE) -> what granularity and level of abstraction are the system analyzed at? | E6: Mostly high and Medium level of abstraction, for example single processes and their communications, microservices, individual storage of sensitive information detailed | F6: =_xlfn.XLOOKUP(E6,lookup!E17:E20,lookup!F17:F20,0) -> 0.75
B7: threat model scalability and composability | C7: QFM3.1 | D7: =_xlfn.XLOOKUP('phase 1 - 2023'!C7,lookup!C7:C49,lookup!D7:D49,FALSE) -> How scalable are the threat models? | E7: bigger systems are divided into multiple threat models and there is clear boundaries among them and assets definition consistency | F7: =_xlfn.XLOOKUP(E7,lookup!E21:E23,lookup!F21:F23,0) -> 1
A8: Staff enablement | B8: Security expertise availability (SME/training/sec champions) | C8: QFSE1.1 | D8: =_xlfn.XLOOKUP('phase 1 - 2023'!C8,lookup!C8:C50,lookup!D8:D50,FALSE) -> what security expertise is available to perform threat modeling? | E8: there are SMEs for ad-hoc threat modeling | F8: =_xlfn.XLOOKUP(E8,lookup!E24:E27,lookup!F24:F27,0) -> 0.33
A9: Measurements and metrics | B9: threat modeling metrics | C9: QFMM2.1 | D9: =_xlfn.XLOOKUP('phase 1 - 2023'!C9,lookup!C9:C51,lookup!D9:D51,FALSE) -> what metrics the TM process produces? | E9: TM completion for every system that needs analysis | F9: =_xlfn.XLOOKUP(E9,lookup!E28:E30,lookup!F28:F30,0) -> 0.5
A10: Threat model lifecycle and capabilities | B10: threat model storage, format, template and tracking | C10: QFENLC1.1 | D10: =_xlfn.XLOOKUP('phase 1 - 2023'!C10,lookup!C10:C52,lookup!D10:D52,FALSE) -> how are TM stored and accessible? | E10: standard storage location is defined and enforced | F10: =_xlfn.XLOOKUP(E10,lookup!E31:E33,lookup!F31:F33,0) -> 0.66
C11: QFENLC1.2 | D11: =_xlfn.XLOOKUP('phase 1 - 2023'!C11,lookup!C11:C53,lookup!D11:D53,FALSE) -> what file format and template are threat models on? | E11: standard format and templates available and used in most threat models | F11: =_xlfn.XLOOKUP(E11,lookup!E34:E36,lookup!F34:F36,0) -> 1
B12: issue tracking/gates | C12: QFIT1.1 | D12: =_xlfn.XLOOKUP('phase 1 - 2023'!C12,lookup!C12:C54,lookup!D12:D54,FALSE) -> how TM outcomes and security issue management are related? | E12: on ad-hoc basis and not consistently TM findings are added to the issue tracking system | F12: =_xlfn.XLOOKUP(E12,lookup!E37:E39,lookup!F37:F39,0) -> 0.5
C13: QFIT1.2 | D13: =_xlfn.XLOOKUP('phase 1 - 2023'!C13,lookup!C13:C55,lookup!D13:D55,FALSE) -> how TM analysis and its outcomes impact the release condition and gates? | E13: TM practices do not affect releases status | F13: =_xlfn.XLOOKUP(E13,lookup!E40:E42,lookup!F40:F42,0) -> 0 | G13: reverted to 0
B19: Maturity 0 - 3
A21: Process integration | B21: =AVERAGE(F2:F4)*3 -> 1.65
A22: Methodology &​ granularity | B22: =AVERAGE(F5:F7)*3 -> 2.41
A23: Staff enablement | B23: =AVERAGE(F4:F6)*3 -> 1.74
A24: Measurements and metrics | B24: =F9*3 -> 1.5
A25: Threat model lifecycle and capabilities | B25: =AVERAGE(F10:F13)*3 -> 1.62
A27: Overall Maturity | B27: =AVERAGE(B21:B25) -> 1.784

Sheet phase 2 - 2024
A1: Feature Category | B1: Feature | C1: QuestionID | D1: Question | E1: Answer | G1: notes
A2: =lookup!A2 -> Process integration | B2: =lookup!B2 -> maintenance and review frequency | C2: =lookup!C2 -> QFPI1.1 | D2: =_xlfn.XLOOKUP('phase 2 - 2024'!C2,lookup!C2:C44,lookup!D2:D44,FALSE) -> How often the threat models are reviewed and maintained? | E2: At least annually and before every release | F2: =_xlfn.XLOOKUP(E2,lookup!E2:E5,lookup!F2:F5,FALSE) -> 1
B3: =lookup!B6 -> Threat Modeling process engagement | C3: =lookup!C6 -> QFPI2.1 | D3: =_xlfn.XLOOKUP('phase 2 - 2024'!C3,lookup!C3:C45,lookup!D3:D45,FALSE) -> On what occasions TM is performed during SSDL? | E3: Integration into software delivery management (e.g. Agile) and using formal quality gates (Def of Done, Def of Ready) for change management and release criteria. | F3: =_xlfn.XLOOKUP(E3,lookup!E6:E9,lookup!F6:F9,FALSE) -> 1 | G3: * trying to align to the cadence of the review * try to align with the design process to achieve this
B4: =lookup!B10 -> SSDL and TM features synergies | C4: =lookup!C10 -> QFPI3.1 | D4: =_xlfn.XLOOKUP('phase 2 - 2024'!C4,lookup!C4:C46,lookup!D4:D46,FALSE) -> How current threat modeling enables and improves other aspects of security and development? | E4: Threat Models are the main reference for securing software architecture and design | F4: =_xlfn.XLOOKUP(E4,lookup!E10:E13,lookup!F10:F13,FALSE) -> 0.66 | G4: * close to define the process woth Omar and security objectives to review every and ereference every signle design
A5: Methodology &​ granularity | B5: methodology and analysis consistency | C5: QFM1.1 | D5: =_xlfn.XLOOKUP('phase 2 - 2024'!C5,lookup!C5:C47,lookup!D5:D47,FALSE) -> what methodologies are used for threat modeling? | E5: Standard and custom methodologies that takes into account specific system threats | F5: =_xlfn.XLOOKUP(E5,lookup!E14:E16,lookup!F14:F16,FALSE) -> 1 | G5: sec objectives checklist and operational guides
B6: granularity and level of abstraction | C6: QFM2.1 | D6: =_xlfn.XLOOKUP('phase 2 - 2024'!C6,lookup!C6:C48,lookup!D6:D48,FALSE) -> what granularity and level of abstraction are the system analyzed at? | E6: Mostly high and Medium level of abstraction, for example single processes and their communications, microservices, individual storage of sensitive information detailed | F6: =_xlfn.XLOOKUP(E6,lookup!E17:E20,lookup!F17:F20,0) -> 0.75
B7: threat model scalability and composability | C7: QFM3.1 | D7: =_xlfn.XLOOKUP('phase 2 - 2024'!C7,lookup!C7:C49,lookup!D7:D49,FALSE) -> How scalable are the threat models? | E7: bigger systems are divided into multiple threat models and there is clear boundaries among them and assets definition consistency | F7: =_xlfn.XLOOKUP(E7,lookup!E21:E23,lookup!F21:F23,0) -> 1
A8: Staff enablement | B8: Security expertise availability (SME/training/sec champions) | C8: QFSE1.1 | D8: =_xlfn.XLOOKUP('phase 2 - 2024'!C8,lookup!C8:C50,lookup!D8:D50,FALSE) -> what security expertise is available to perform threat modeling? | E8: there are SMEs for ad-hoc threat modeling and training available | F8: =_xlfn.XLOOKUP(E8,lookup!E24:E27,lookup!F24:F27,0) -> 0.66
A9: Measurements and metrics | B9: threat modeling metrics | C9: QFMM2.1 | D9: =_xlfn.XLOOKUP('phase 2 - 2024'!C9,lookup!C9:C51,lookup!D9:D51,FALSE) -> what metrics the TM process produces? | E9: TM completion for every system that needs analysis | F9: =_xlfn.XLOOKUP(E9,lookup!E28:E30,lookup!F28:F30,0) -> 0.5
A10: Threat model lifecycle and capabilities | B10: threat model storage, format, template and tracking | C10: QFENLC1.1 | D10: =_xlfn.XLOOKUP('phase 2 - 2024'!C10,lookup!C10:C52,lookup!D10:D52,FALSE) -> how are TM stored and accessible? | E10: TM are stored and versioned using compliant tools and access control | F10: =_xlfn.XLOOKUP(E10,lookup!E31:E33,lookup!F31:F33,0) -> 1
C11: QFENLC1.2 | D11: =_xlfn.XLOOKUP('phase 2 - 2024'!C11,lookup!C11:C53,lookup!D11:D53,FALSE) -> what file format and template are threat models on? | E11: standard format and templates available and used in most threat models | F11: =_xlfn.XLOOKUP(E11,lookup!E34:E36,lookup!F34:F36,0) -> 1
B12: issue tracking/gates | C12: QFIT1.1 | D12: =_xlfn.XLOOKUP('phase 2 - 2024'!C12,lookup!C12:C54,lookup!D12:D54,FALSE) -> how TM outcomes and security issue management are related? | E12: TM outcomes are part of the security issue bucket and prioritized | F12: =_xlfn.XLOOKUP(E12,lookup!E37:E39,lookup!F37:F39,0) -> 1 | G12: Aim at being better!
C13: QFIT1.2 | D13: =_xlfn.XLOOKUP('phase 2 - 2024'!C13,lookup!C13:C55,lookup!D13:D55,FALSE) -> how TM analysis and its outcomes impact the release condition and gates? | E13: on ad-hoc basis and not consistently TM findings are affecting releases status | F13: =_xlfn.XLOOKUP(E13,lookup!E40:E42,lookup!F40:F42,0) -> 0.5
B19: Maturity 0 - 3
A21: Process integration | B21: =AVERAGE(F2:F4)*3 -> 2.66
A22: Methodology &​ granularity | B22: =AVERAGE(F5:F7)*3 -> 2.75
A23: Staff enablement | B23: =AVERAGE(F4:F6)*3 -> 2.41
A24: Measurements and metrics | B24: =F9*3 -> 1.5
A25: Threat model lifecycle and capabilities | B25: =AVERAGE(F10:F13)*3 -> 2.625
A27: Overall Maturity | B27: =AVERAGE(B21:B25) -> 2.389

Sheet pivot
A1: Sum of Maturity | B1: Column Labels
A2: Row Labels | B2: Current | C2: Phase1 | D2: Phase2 | E2: Grand Total
A3: Measurements and metrics | B3: 0 | C3: 1.5 | D3: 3 | E3: 4.5
A4: Methodology &​ granularity | B4: 1.16 | C4: 2.41 | D4: 2.75 | E4: 6.32
A5: Process integration | B5: 0.33 | C5: 1.65 | D5: 2.66 | E5: 4.64
A6: Staff enablement | B6: 1.16 | C6: 1.74 | D6: 2.41 | E6: 5.31
A7: Threat model lifecycle and capabilities | B7: 0.375 | C7: 2.37 | D7: 3 | E7: 5.745
A8: Grand Total | B8: 3.025 | C8: 9.67 | D8: 13.82 | E8: 26.515
A11: Phase | B11: Feature Category | C11: Maturity
A12: init 2022 | B12: {='initial - circa 2022'!A21:B25} -> Process integration | C12: 0.33
A13: init 2022 | B13: Methodology &​ granularity | C13: 1.16
A14: init 2022 | B14: Staff enablement | C14: 1.16
A15: init 2022 | B15: Measurements and metrics | C15: 0
A16: init 2022 | B16: Threat model lifecycle and capabilities | C16: 0.375
A17: Phase1 - 2023 | B17: {='phase 1 - 2023'!$A$21:$B$25} -> Process integration | C17: 1.65
A18: Phase1 - 2023 | B18: Methodology &​ granularity | C18: 2.41
A19: Phase1 - 2023 | B19: Staff enablement | C19: 1.74
A20: Phase1 - 2023 | B20: Measurements and metrics | C20: 1.5
A21: Phase1 - 2023 | B21: Threat model lifecycle and capabilities | C21: 1.62
A22: Phase2 - 2024 | B22: {='phase 2 - 2024'!A21:B25} -> Process integration | C22: 2.66
A23: Phase2 - 2024 | B23: Methodology &​ granularity | C23: 2.75
A24: Phase2 - 2024 | B24: Staff enablement | C24: 2.41
A25: Phase2 - 2024 | B25: Measurements and metrics | C25: 1.5
A26: Phase2 - 2024 | B26: Threat model lifecycle and capabilities | C26: 2.625
A29: Average of Maturity | B29: Column Labels
A30: Row Labels | B30: init 2022 | C30: Phase1 - 2023 | D30: Phase2 - 2024 | E30: Grand Total
A31: Measurements and metrics | B31: 0 | C31: 1.5 | D31: 1.5 | E31: 1
A32: Methodology &​ granularity | B32: 1.16 | C32: 2.41 | D32: 2.75 | E32: 2.1066667
A33: Process integration | B33: 0.33 | C33: 1.65 | D33: 2.66 | E33: 1.5466667
A34: Staff enablement | B34: 1.16 | C34: 1.74 | D34: 2.41 | E34: 1.77
A35: Threat model lifecycle and capabilities | B35: 0.375 | C35: 1.62 | D35: 2.625 | E35: 1.54
A36: Grand Total | B36: 0.605 | C36: 1.784 | D36: 2.389 | E36: 1.5926667
A59: init 2022 | B59: 0.605
A60: Phase1 -2023 | B60: 1.784
A61: Phase2 - 2024 | B61: 2.389

Sheet reports

Sheet lookup
A1: Feature Categoty | B1: feature | C1: QuestionID | D1: Questiontext | E1: answer | F1: weight
A2: Process integration | B2: maintenance and review frequency | C2: QFPI1.1 | D2: How often the threat models are reviewed and maintained? | E2: No defined frequency | F2: 0
E3: Periodically | F3: 0.33
E4: At least annually | F4: 0.66
E5: At least annually and before every release | F5: 1
B6: Threat Modeling process engagement | C6: QFPI2.1 | D6: On what occasions TM is performed during SSDL? | E6: Never performed | F6: 0
E7: On ad-hoc basis | F7: 0.33
E8: Modelling performed as part of standard process that is loosely aligned to release processes | F8: 0.66
E9: Integration into software delivery management (e.g. Agile) and using formal quality gates (Def of Done, Def of Ready) for change management and release criteria. | F9: 1
B10: SSDL and TM features synergies | C10: QFPI3.1 | D10: How current threat modeling enables and improves other aspects of security and development? | E10: Threat Models are not present or if present are mostly ignored and unused to improve other aspects of development | F10: 0
E11: on ad-hoc basis threat models are used (for example as a reference documentation, or for customers request, or as compliance evidence) | F11: 0.33
E12: Threat Models are the main reference for securing software architecture and design | F12: 0.66
E13: Threat Models findings and the identified mitigations feed at least some specific secure development practices, for example, dynamic testing, manual regression testing, penetration testing, static/dynamic/composition/interactive analysis | F13: 1
A14: Methodology &​ granularity | B14: methodology and analysis consistency | C14: QFM1.1 | D14: what methodologies are used for threat modeling? | E14: No use of any methodologies or no analysis | F14: 0
E15: Standard methodologies for example:data flow analysis, STRIDE, attack trees, trust boundaries definition, etc. | F15: 0.66
E16: Standard and custom methodologies that takes into account specific system threats | F16: 1
B17: granularity and level of abstraction | C17: QFM2.1 | D17: what granularity and level of abstraction are the system analyzed at? | E17: No analysis at all | F17: 0
E18: Mostly high level of abstraction, for example Data Flow Diagrams and high level architecture and system views | F18: 0.5
E19: Mostly high and Medium level of abstraction, for example single processes and their communications, microservices, individual storage of sensitive information detailed | F19: 0.75
E20: Both high level and single features level (single API endpoints, sequence diagrams, feature abuse cases) | F20: 1
B21: threat model scalability and composability | C21: QFM3.1 | D21: How scalable are the threat models? | E21: every threat model is logically not compatible with the others threat models | F21: 0
E22: bigger systems are divided into multiple threat models but there is not clear boundaries among them and assets and scope definition consistency | F22: 0.5
E23: bigger systems are divided into multiple threat models and there is clear boundaries among them and assets definition consistency | F23: 1
A24: Staff enablement | B24: Security expertise availability (SME/training/sec champions) | C24: QFSE1.1 | D24: what security expertise is available to perform threat modeling? | E24: security expertise for threat modeling mostly unavailable and difficult to find in the organization | F24: 0
E25: there are SMEs for ad-hoc threat modeling | F25: 0.33
E26: there are SMEs for ad-hoc threat modeling and training available | F26: 0.66
E27: there are SMEs and consistent training (for example security champions) | F27: 1
A28: Measurements and metrics | B28: threat modeling metrics | C28: QFMM2.1 | D28: what metrics the TM process produces? | E28: no metrics | F28: 0
E29: TM completion for every system that needs analysis | F29: 0.5
E30: TM outcomes contributes to the overall system risk management/evaluation | F30: 1
A31: Threat model lifecycle and capabilities | B31: threat model storage, format, template and tracking | C31: QFENLC1.1 | D31: how are TM stored and accessible? | E31: not defined, and no consistent way to retrieve threat models | F31: 0
E32: standard storage location is defined and enforced | F32: 0.66
E33: TM are stored and versioned using compliant tools and access control | F33: 1
C34: QFENLC1.2 | D34: what file format and template are threat models on? | E34: not defined | F34: 0
E35: standard format and templates available but not used in most threat models | F35: 0.5
E36: standard format and templates available and used in most threat models | F36: 1
B37: issue tracking/gates | C37: QFIT1.1 | D37: how TM outcomes and security issue management are related? | E37: not defined | F37: 0
E38: on ad-hoc basis and not consistently TM findings are added to the issue tracking system | F38: 0.5
E39: TM outcomes are part of the security issue bucket and prioritized | F39: 1
C40: QFIT1.2 | D40: how TM analysis and its outcomes impact the release condition and gates? | E40: TM practices do not affect releases status | F40: 0
...
